[2023-07-23T06:08:09.191+0000] {taskinstance.py:1165} INFO - Dependencies all met for <TaskInstance: xcom_dag.t2 scheduled__2023-07-22T00:00:00+00:00 [queued]>
[2023-07-23T06:08:09.198+0000] {taskinstance.py:1165} INFO - Dependencies all met for <TaskInstance: xcom_dag.t2 scheduled__2023-07-22T00:00:00+00:00 [queued]>
[2023-07-23T06:08:09.198+0000] {taskinstance.py:1362} INFO - 
--------------------------------------------------------------------------------
[2023-07-23T06:08:09.198+0000] {taskinstance.py:1363} INFO - Starting attempt 1 of 1
[2023-07-23T06:08:09.198+0000] {taskinstance.py:1364} INFO - 
--------------------------------------------------------------------------------
[2023-07-23T06:08:09.207+0000] {taskinstance.py:1383} INFO - Executing <Task(PythonOperator): t2> on 2023-07-22 00:00:00+00:00
[2023-07-23T06:08:09.211+0000] {standard_task_runner.py:55} INFO - Started process 29320 to run task
[2023-07-23T06:08:09.215+0000] {standard_task_runner.py:82} INFO - Running: ['***', 'tasks', 'run', 'xcom_dag', 't2', 'scheduled__2023-07-22T00:00:00+00:00', '--job-id', '184', '--raw', '--subdir', 'DAGS_FOLDER/xcom_dag.py', '--cfg-path', '/tmp/tmpzq9re9lk']
[2023-07-23T06:08:09.216+0000] {standard_task_runner.py:83} INFO - Job 184: Subtask t2
[2023-07-23T06:08:09.272+0000] {task_command.py:376} INFO - Running <TaskInstance: xcom_dag.t2 scheduled__2023-07-22T00:00:00+00:00 [running]> on host ef71d3f52879
[2023-07-23T06:08:09.334+0000] {taskinstance.py:1592} INFO - Exporting the following env vars:
AIRFLOW_CTX_DAG_OWNER=***
AIRFLOW_CTX_DAG_ID=xcom_dag
AIRFLOW_CTX_TASK_ID=t2
AIRFLOW_CTX_EXECUTION_DATE=2023-07-22T00:00:00+00:00
AIRFLOW_CTX_TRY_NUMBER=1
AIRFLOW_CTX_DAG_RUN_ID=scheduled__2023-07-22T00:00:00+00:00
[2023-07-23T06:08:09.335+0000] {taskinstance.py:1851} ERROR - Task failed with exception
Traceback (most recent call last):
  File "/home/airflow/.local/lib/python3.7/site-packages/airflow/operators/python.py", line 175, in execute
    return_value = self.execute_callable()
  File "/home/airflow/.local/lib/python3.7/site-packages/airflow/operators/python.py", line 193, in execute_callable
    return self.python_callable(*self.op_args, **self.op_kwargs)
  File "/opt/airflow/dags/xcom_dag.py", line 13, in _t2
    ti.xcom_push(key='my_key', task_ids='t1')
  File "/home/airflow/.local/lib/python3.7/site-packages/airflow/utils/session.py", line 75, in wrapper
    return func(*args, session=session, **kwargs)
TypeError: xcom_push() got an unexpected keyword argument 'task_ids'
[2023-07-23T06:08:09.348+0000] {taskinstance.py:1406} INFO - Marking task as FAILED. dag_id=xcom_dag, task_id=t2, execution_date=20230722T000000, start_date=20230723T060809, end_date=20230723T060809
[2023-07-23T06:08:09.357+0000] {standard_task_runner.py:105} ERROR - Failed to execute job 184 for task t2 (xcom_push() got an unexpected keyword argument 'task_ids'; 29320)
[2023-07-23T06:08:09.387+0000] {local_task_job.py:164} INFO - Task exited with return code 1
[2023-07-23T06:08:09.413+0000] {local_task_job.py:273} INFO - 0 downstream tasks scheduled from follow-on schedule check
